............................FFF..FF....F...........................F...F [  9%]
FF.........................ss..F..F.F.F.FF.F..ssssssss.................. [ 18%]
ssEEE......F.EEE....FFFF...................................F............ [ 27%]
........................................................................ [ 36%]
...FFF..............................FFF................................. [ 45%]
.........................F...........................FF.F...F....F...... [ 55%]
..FFF...FFFF...............sssssss................sssss..............ss. [ 64%]
.........F...........................................FFF....F..FFFFF.FFs [ 73%]
s.........FFFFFF.FFFFF....F............................................. [ 82%]
........................................................................ [ 91%]
.................................................................        [100%]
============================== warnings summary ===============================
tests/unit/test_metrics_collector.py::TestSystemMetricsSource::test_system_metrics_error_handling
  C:\Users\kevin\Desktop\ElectroAnalyzer\venv_test\Lib\site-packages\_pytest\_code\code.py:369: RuntimeWarning: coroutine 'TestSystemMetricsSource.test_system_metrics_collection' was never awaited
    yield TracebackEntry(cur_)
  Enable tracemalloc to get traceback where the object was allocated.
  See https://docs.pytest.org/en/stable/how-to/capture-warnings.html#resource-warnings for more info.

tests/unit/test_metrics_collector.py::TestMetricsCollector::test_collector_initialization
  <frozen abc>:123: RuntimeWarning: coroutine 'TestApplicationMetricsSource.test_application_metrics_collection' was never awaited
  Enable tracemalloc to get traceback where the object was allocated.
  See https://docs.pytest.org/en/stable/how-to/capture-warnings.html#resource-warnings for more info.

tests/unit/test_metrics_collector.py::TestMetricsCollector::test_collector_initialization
  <frozen abc>:123: RuntimeWarning: coroutine 'TestAIModelMetricsSource.test_ai_metrics_collection' was never awaited
  Enable tracemalloc to get traceback where the object was allocated.
  See https://docs.pytest.org/en/stable/how-to/capture-warnings.html#resource-warnings for more info.

tests/unit/test_metrics_collector.py::TestGlobalFunctions::test_convenience_functions_error_handling
  C:\Users\kevin\Desktop\ElectroAnalyzer\src\core\metrics_collector.py:934: RuntimeWarning: coroutine 'TestMetricsCollector.test_metrics_collection' was never awaited
    collector = get_metrics_collector()
  Enable tracemalloc to get traceback where the object was allocated.
  See https://docs.pytest.org/en/stable/how-to/capture-warnings.html#resource-warnings for more info.

tests/unit/test_ml_trainer.py::TestMLTrainingPipeline::test_should_retrain_time_based
  C:\Users\kevin\AppData\Local\Programs\Python\Python311\Lib\inspect.py:3062: RuntimeWarning: coroutine 'TestMLTrainingPipeline.test_insufficient_training_data' was never awaited
    arguments = {}
  Enable tracemalloc to get traceback where the object was allocated.
  See https://docs.pytest.org/en/stable/how-to/capture-warnings.html#resource-warnings for more info.

tests/unit/test_ml_trainer.py::TestMLTrainingPipeline::test_should_retrain_time_based
  C:\Users\kevin\AppData\Local\Programs\Python\Python311\Lib\inspect.py:3062: RuntimeWarning: coroutine 'TestMLTrainingPipeline.test_successful_training_and_deployment' was never awaited
    arguments = {}
  Enable tracemalloc to get traceback where the object was allocated.
  See https://docs.pytest.org/en/stable/how-to/capture-warnings.html#resource-warnings for more info.

tests/unit/test_ml_trainer.py::test_legacy_function_compatibility
  C:\Users\kevin\Desktop\ElectroAnalyzer\venv_test\Lib\site-packages\_pytest\nodes.py:344: RuntimeWarning: coroutine 'TestMLTrainingPipeline.test_training_error_handling' was never awaited
    return (x[1] for x in self.iter_markers_with_node(name=name))
  Enable tracemalloc to get traceback where the object was allocated.
  See https://docs.pytest.org/en/stable/how-to/capture-warnings.html#resource-warnings for more info.

tests/unit/test_ml_trainer.py::test_legacy_function_compatibility
  C:\Users\kevin\Desktop\ElectroAnalyzer\venv_test\Lib\site-packages\_pytest\nodes.py:344: RuntimeWarning: coroutine 'TestMLTrainingPipeline.test_skipped_training_due_to_time' was never awaited
    return (x[1] for x in self.iter_markers_with_node(name=name))
  Enable tracemalloc to get traceback where the object was allocated.
  See https://docs.pytest.org/en/stable/how-to/capture-warnings.html#resource-warnings for more info.

tests/unit/test_ner.py::TestNERPipeline::test_initialization_with_empty_models
  C:\Users\kevin\AppData\Local\Programs\Python\Python311\Lib\configparser.py:1267: RuntimeWarning: coroutine 'TestSystemMetricsSource.test_system_metrics_error_handling' was never awaited
    getter = functools.partial(self.get, _impl=getattr(parser, key))
  Enable tracemalloc to get traceback where the object was allocated.
  See https://docs.pytest.org/en/stable/how-to/capture-warnings.html#resource-warnings for more info.

tests/unit/test_ner.py::TestNERPipeline::test_initialization_with_empty_models
  C:\Users\kevin\AppData\Local\Programs\Python\Python311\Lib\configparser.py:1267: RuntimeWarning: coroutine 'TestMLTrainingPipeline.test_training_with_insufficient_improvement' was never awaited
    getter = functools.partial(self.get, _impl=getattr(parser, key))
  Enable tracemalloc to get traceback where the object was allocated.
  See https://docs.pytest.org/en/stable/how-to/capture-warnings.html#resource-warnings for more info.

tests/unit/test_ner.py::TestNERPipeline::test_initialization_with_empty_models
  C:\Users\kevin\AppData\Local\Programs\Python\Python311\Lib\configparser.py:1267: RuntimeWarning: coroutine 'test_legacy_function_compatibility' was never awaited
    getter = functools.partial(self.get, _impl=getattr(parser, key))
  Enable tracemalloc to get traceback where the object was allocated.
  See https://docs.pytest.org/en/stable/how-to/capture-warnings.html#resource-warnings for more info.

tests/unit/test_ner.py::TestNERPipeline::test_initialization_with_empty_models
  C:\Users\kevin\AppData\Local\Programs\Python\Python311\Lib\configparser.py:1267: RuntimeWarning: coroutine 'TestMLTrainingIntegration.test_end_to_end_training_pipeline' was never awaited
    getter = functools.partial(self.get, _impl=getattr(parser, key))
  Enable tracemalloc to get traceback where the object was allocated.
  See https://docs.pytest.org/en/stable/how-to/capture-warnings.html#resource-warnings for more info.

tests/unit/test_performance_optimizer.py::TestCacheWarmingService::test_execute_warming
  C:\Users\kevin\Desktop\ElectroAnalyzer\venv_test\Lib\site-packages\pytest_asyncio\plugin.py:533: RuntimeWarning: coroutine 'TestBatchCacheOperations.test_batch_get_embeddings' was never awaited
    super().runtest()
  Enable tracemalloc to get traceback where the object was allocated.
  See https://docs.pytest.org/en/stable/how-to/capture-warnings.html#resource-warnings for more info.

tests/unit/test_performance_optimizer.py::TestCacheWarmingService::test_execute_warming
  C:\Users\kevin\Desktop\ElectroAnalyzer\venv_test\Lib\site-packages\pytest_asyncio\plugin.py:533: RuntimeWarning: coroutine 'TestBatchCacheOperations.test_batch_set_embeddings' was never awaited
    super().runtest()
  Enable tracemalloc to get traceback where the object was allocated.
  See https://docs.pytest.org/en/stable/how-to/capture-warnings.html#resource-warnings for more info.

tests/unit/test_performance_optimizer.py::TestCacheWarmingService::test_execute_warming
  C:\Users\kevin\Desktop\ElectroAnalyzer\venv_test\Lib\site-packages\pytest_asyncio\plugin.py:533: RuntimeWarning: coroutine 'TestBatchCacheOperations.test_batch_get_ner_results' was never awaited
    super().runtest()
  Enable tracemalloc to get traceback where the object was allocated.
  See https://docs.pytest.org/en/stable/how-to/capture-warnings.html#resource-warnings for more info.

tests/unit/test_performance_optimizer.py::TestPerformanceOptimizer::test_generate_optimization_recommendations
  C:\Users\kevin\Desktop\ElectroAnalyzer\venv_test\Lib\site-packages\_pytest\_code\code.py:369: RuntimeWarning: coroutine 'TestPerformanceOptimizer.test_analyze_performance' was never awaited
    yield TracebackEntry(cur_)
  Enable tracemalloc to get traceback where the object was allocated.
  See https://docs.pytest.org/en/stable/how-to/capture-warnings.html#resource-warnings for more info.

tests/unit/test_performance_optimizer.py::TestPerformanceOptimizer::test_generate_optimization_recommendations
  C:\Users\kevin\Desktop\ElectroAnalyzer\venv_test\Lib\site-packages\_pytest\_code\code.py:369: RuntimeWarning: coroutine 'TestPerformanceOptimizer.test_optimize_performance' was never awaited
    yield TracebackEntry(cur_)
  Enable tracemalloc to get traceback where the object was allocated.
  See https://docs.pytest.org/en/stable/how-to/capture-warnings.html#resource-warnings for more info.

tests/unit/test_performance_optimizer.py::TestPerformanceOptimizer::test_generate_optimization_recommendations
  C:\Users\kevin\Desktop\ElectroAnalyzer\venv_test\Lib\site-packages\_pytest\_code\code.py:369: RuntimeWarning: coroutine 'TestPerformanceOptimizer.test_identify_bottlenecks' was never awaited
    yield TracebackEntry(cur_)
  Enable tracemalloc to get traceback where the object was allocated.
  See https://docs.pytest.org/en/stable/how-to/capture-warnings.html#resource-warnings for more info.

tests/unit/test_performance_optimizer.py::TestPerformanceOptimizer::test_performance_analysis_with_real_cache
  C:\Users\kevin\Desktop\ElectroAnalyzer\venv_test\Lib\site-packages\_pytest\runner.py:539: RuntimeWarning: coroutine 'TestPerformanceOptimizer.test_calculate_performance_improvements' was never awaited
    if list(self.stack.keys()) == needed_collectors[: len(self.stack)]:
  Enable tracemalloc to get traceback where the object was allocated.
  See https://docs.pytest.org/en/stable/how-to/capture-warnings.html#resource-warnings for more info.

tests/unit/test_performance_optimizer.py::TestPerformanceOptimizer::test_performance_analysis_with_real_cache
  C:\Users\kevin\Desktop\ElectroAnalyzer\venv_test\Lib\site-packages\_pytest\runner.py:539: RuntimeWarning: coroutine 'TestPerformanceOptimizer.test_memory_optimization' was never awaited
    if list(self.stack.keys()) == needed_collectors[: len(self.stack)]:
  Enable tracemalloc to get traceback where the object was allocated.
  See https://docs.pytest.org/en/stable/how-to/capture-warnings.html#resource-warnings for more info.

tests/unit/test_performance_test_orchestrator.py::TestExecutionEngine::test_execute_test_no_runner
  C:\Users\kevin\Desktop\ElectroAnalyzer\venv_test\Lib\site-packages\pluggy\_callers.py:135: RuntimeWarning: coroutine 'TestExecutionEngine.test_execute_test_success' was never awaited
    for teardown in reversed(teardowns):
  Enable tracemalloc to get traceback where the object was allocated.
  See https://docs.pytest.org/en/stable/how-to/capture-warnings.html#resource-warnings for more info.

tests/unit/test_performance_test_orchestrator.py::TestExecutionEngine::test_execute_test_no_runner
  C:\Users\kevin\Desktop\ElectroAnalyzer\venv_test\Lib\site-packages\pluggy\_callers.py:135: RuntimeWarning: coroutine 'TestExecutionEngine.test_execute_test_failure' was never awaited
    for teardown in reversed(teardowns):
  Enable tracemalloc to get traceback where the object was allocated.
  See https://docs.pytest.org/en/stable/how-to/capture-warnings.html#resource-warnings for more info.

tests/unit/test_performance_test_orchestrator.py::TestExecutionEngine::test_execute_test_no_runner
  C:\Users\kevin\Desktop\ElectroAnalyzer\venv_test\Lib\site-packages\pluggy\_callers.py:135: RuntimeWarning: coroutine 'TestExecutionEngine.test_execute_test_timeout' was never awaited
    for teardown in reversed(teardowns):
  Enable tracemalloc to get traceback where the object was allocated.
  See https://docs.pytest.org/en/stable/how-to/capture-warnings.html#resource-warnings for more info.

tests/unit/test_performance_test_orchestrator.py::TestPerformanceTestOrchestrator::test_run_optimization_tests
  C:\Users\kevin\Desktop\ElectroAnalyzer\venv_test\Lib\site-packages\_pytest\_code\code.py:369: RuntimeWarning: coroutine 'TestExecutionEngine.test_execute_tests_parallel' was never awaited
    yield TracebackEntry(cur_)
  Enable tracemalloc to get traceback where the object was allocated.
  See https://docs.pytest.org/en/stable/how-to/capture-warnings.html#resource-warnings for more info.

tests/unit/test_performance_test_orchestrator.py::TestPerformanceTestOrchestrator::test_run_optimization_tests
  C:\Users\kevin\Desktop\ElectroAnalyzer\venv_test\Lib\site-packages\_pytest\_code\code.py:369: RuntimeWarning: coroutine 'TestExecutionEngine.test_execute_tests_parallel_with_disabled' was never awaited
    yield TracebackEntry(cur_)
  Enable tracemalloc to get traceback where the object was allocated.
  See https://docs.pytest.org/en/stable/how-to/capture-warnings.html#resource-warnings for more info.

tests/unit/test_performance_test_orchestrator.py::TestPerformanceTestOrchestrator::test_run_optimization_tests
  C:\Users\kevin\Desktop\ElectroAnalyzer\venv_test\Lib\site-packages\_pytest\_code\code.py:369: RuntimeWarning: coroutine 'TestPerformanceTestOrchestrator.test_run_baseline_tests' was never awaited
    yield TracebackEntry(cur_)
  Enable tracemalloc to get traceback where the object was allocated.
  See https://docs.pytest.org/en/stable/how-to/capture-warnings.html#resource-warnings for more info.

tests/unit/test_performance_test_orchestrator.py::test_integration_full_workflow
  C:\Users\kevin\Desktop\ElectroAnalyzer\venv_test\Lib\site-packages\pluggy\_callers.py:53: RuntimeWarning: coroutine 'TestPerformanceTestOrchestrator.test_run_test_suite' was never awaited
    return result.get_result()
  Enable tracemalloc to get traceback where the object was allocated.
  See https://docs.pytest.org/en/stable/how-to/capture-warnings.html#resource-warnings for more info.

tests/unit/test_performance_test_orchestrator.py::test_integration_full_workflow
  C:\Users\kevin\Desktop\ElectroAnalyzer\venv_test\Lib\site-packages\pluggy\_callers.py:53: RuntimeWarning: coroutine 'TestPerformanceTestOrchestrator.test_run_full_performance_suite' was never awaited
    return result.get_result()
  Enable tracemalloc to get traceback where the object was allocated.
  See https://docs.pytest.org/en/stable/how-to/capture-warnings.html#resource-warnings for more info.

tests/unit/test_performance_test_orchestrator.py::test_integration_full_workflow
  C:\Users\kevin\Desktop\ElectroAnalyzer\venv_test\Lib\site-packages\pluggy\_callers.py:53: RuntimeWarning: coroutine 'TestPerformanceTestOrchestrator.test_run_nonexistent_suite' was never awaited
    return result.get_result()
  Enable tracemalloc to get traceback where the object was allocated.
  See https://docs.pytest.org/en/stable/how-to/capture-warnings.html#resource-warnings for more info.

tests/unit/test_query_expander.py::TestMedicalVocabulary::test_save_and_load_vocabulary
  C:\Users\kevin\AppData\Local\Programs\Python\Python311\Lib\json\encoder.py:432: RuntimeWarning: coroutine 'TestCacheWarmingService.test_execute_warming' was never awaited
    yield from _iterencode_dict(o, _current_indent_level)
  Enable tracemalloc to get traceback where the object was allocated.
  See https://docs.pytest.org/en/stable/how-to/capture-warnings.html#resource-warnings for more info.

tests/unit/test_query_expander.py::TestMedicalVocabulary::test_save_and_load_vocabulary
  C:\Users\kevin\AppData\Local\Programs\Python\Python311\Lib\json\encoder.py:432: RuntimeWarning: coroutine 'TestPerformanceOptimizer.test_generate_optimization_recommendations' was never awaited
    yield from _iterencode_dict(o, _current_indent_level)
  Enable tracemalloc to get traceback where the object was allocated.
  See https://docs.pytest.org/en/stable/how-to/capture-warnings.html#resource-warnings for more info.

tests/unit/test_query_expander.py::TestMedicalVocabulary::test_save_and_load_vocabulary
  C:\Users\kevin\AppData\Local\Programs\Python\Python311\Lib\json\encoder.py:432: RuntimeWarning: coroutine 'TestPerformanceOptimizer.test_proactive_warming' was never awaited
    yield from _iterencode_dict(o, _current_indent_level)
  Enable tracemalloc to get traceback where the object was allocated.
  See https://docs.pytest.org/en/stable/how-to/capture-warnings.html#resource-warnings for more info.

tests/unit/test_query_expander.py::TestMedicalVocabulary::test_save_and_load_vocabulary
2025-10-21 14:44:51,790 - asyncio - ERROR - Task was destroyed but it is pending!
task: <Task pending name='Task-14309' coro=<MultiTierCacheSystem._metrics_reset_task() running at C:\Users\kevin\Desktop\ElectroAnalyzer\src\core\multi_tier_cache.py:626> wait_for=<Future pending cb=[Task.task_wakeup()]>>
Task was destroyed but it is pending!
task: <Task pending name='Task-14309' coro=<MultiTierCacheSystem._metrics_reset_task() running at C:\Users\kevin\Desktop\ElectroAnalyzer\src\core\multi_tier_cache.py:626> wait_for=<Future pending cb=[Task.task_wakeup()]>>
Task was destroyed but it is pending!
task: <Task pending name='Task-14309' coro=<MultiTierCacheSystem._metrics_reset_task() running at C:\Users\kevin\Desktop\ElectroAnalyzer\src\core\multi_tier_cache.py:626> wait_for=<Future pending cb=[Task.task_wakeup()]>>
2025-10-21 14:44:51,790 - asyncio - ERROR - Task was destroyed but it is pending!
task: <Task pending name='Task-14278' coro=<MultiTierCacheSystem._metrics_reset_task() running at C:\Users\kevin\Desktop\ElectroAnalyzer\src\core\multi_tier_cache.py:626> wait_for=<Future pending cb=[Task.task_wakeup()]>>
Task was destroyed but it is pending!
task: <Task pending name='Task-14278' coro=<MultiTierCacheSystem._metrics_reset_task() running at C:\Users\kevin\Desktop\ElectroAnalyzer\src\core\multi_tier_cache.py:626> wait_for=<Future pending cb=[Task.task_wakeup()]>>
Task was destroyed but it is pending!
task: <Task pending name='Task-14278' coro=<MultiTierCacheSystem._metrics_reset_task() running at C:\Users\kevin\Desktop\ElectroAnalyzer\src\core\multi_tier_cache.py:626> wait_for=<Future pending cb=[Task.task_wakeup()]>>
2025-10-21 14:44:51,790 - asyncio - ERROR - Task was destroyed but it is pending!
task: <Task pending name='Task-14306' coro=<MultiTierCacheSystem._metrics_reset_task() running at C:\Users\kevin\Desktop\ElectroAnalyzer\src\core\multi_tier_cache.py:626> wait_for=<Future pending cb=[Task.task_wakeup()]>>
Task was destroyed but it is pending!
task: <Task pending name='Task-14306' coro=<MultiTierCacheSystem._metrics_reset_task() running at C:\Users\kevin\Desktop\ElectroAnalyzer\src\core\multi_tier_cache.py:626> wait_for=<Future pending cb=[Task.task_wakeup()]>>
Task was destroyed but it is pending!
task: <Task pending name='Task-14306' coro=<MultiTierCacheSystem._metrics_reset_task() running at C:\Users\kevin\Desktop\ElectroAnalyzer\src\core\multi_tier_cache.py:626> wait_for=<Future pending cb=[Task.task_wakeup()]>>
2025-10-21 14:44:51,790 - asyncio - ERROR - Task was destroyed but it is pending!
task: <Task pending name='Task-14290' coro=<MultiTierCacheSystem._metrics_reset_task() running at C:\Users\kevin\Desktop\ElectroAnalyzer\src\core\multi_tier_cache.py:626> wait_for=<Future pending cb=[Task.task_wakeup()]>>
Task was destroyed but it is pending!
task: <Task pending name='Task-14290' coro=<MultiTierCacheSystem._metrics_reset_task() running at C:\Users\kevin\Desktop\ElectroAnalyzer\src\core\multi_tier_cache.py:626> wait_for=<Future pending cb=[Task.task_wakeup()]>>
Task was destroyed but it is pending!
task: <Task pending name='Task-14290' coro=<MultiTierCacheSystem._metrics_reset_task() running at C:\Users\kevin\Desktop\ElectroAnalyzer\src\core\multi_tier_cache.py:626> wait_for=<Future pending cb=[Task.task_wakeup()]>>
2025-10-21 14:44:51,790 - asyncio - ERROR - Task was destroyed but it is pending!
task: <Task pending name='Task-14303' coro=<MultiTierCacheSystem._metrics_reset_task() running at C:\Users\kevin\Desktop\ElectroAnalyzer\src\core\multi_tier_cache.py:626> wait_for=<Future pending cb=[Task.task_wakeup()]>>
Task was destroyed but it is pending!
task: <Task pending name='Task-14303' coro=<MultiTierCacheSystem._metrics_reset_task() running at C:\Users\kevin\Desktop\ElectroAnalyzer\src\core\multi_tier_cache.py:626> wait_for=<Future pending cb=[Task.task_wakeup()]>>
Task was destroyed but it is pending!
task: <Task pending name='Task-14303' coro=<MultiTierCacheSystem._metrics_reset_task() running at C:\Users\kevin\Desktop\ElectroAnalyzer\src\core\multi_tier_cache.py:626> wait_for=<Future pending cb=[Task.task_wakeup()]>>
2025-10-21 14:44:51,790 - asyncio - ERROR - Task was destroyed but it is pending!
task: <Task pending name='Task-14294' coro=<MultiTierCacheSystem._metrics_reset_task() running at C:\Users\kevin\Desktop\ElectroAnalyzer\src\core\multi_tier_cache.py:626> wait_for=<Future pending cb=[Task.task_wakeup()]>>
Task was destroyed but it is pending!
task: <Task pending name='Task-14294' coro=<MultiTierCacheSystem._metrics_reset_task() running at C:\Users\kevin\Desktop\ElectroAnalyzer\src\core\multi_tier_cache.py:626> wait_for=<Future pending cb=[Task.task_wakeup()]>>
Task was destroyed but it is pending!
task: <Task pending name='Task-14294' coro=<MultiTierCacheSystem._metrics_reset_task() running at C:\Users\kevin\Desktop\ElectroAnalyzer\src\core\multi_tier_cache.py:626> wait_for=<Future pending cb=[Task.task_wakeup()]>>
2025-10-21 14:44:51,790 - asyncio - ERROR - Task was destroyed but it is pending!
task: <Task pending name='Task-14300' coro=<MultiTierCacheSystem._metrics_reset_task() running at C:\Users\kevin\Desktop\ElectroAnalyzer\src\core\multi_tier_cache.py:626> wait_for=<Future pending cb=[Task.task_wakeup()]>>
Task was destroyed but it is pending!
task: <Task pending name='Task-14300' coro=<MultiTierCacheSystem._metrics_reset_task() running at C:\Users\kevin\Desktop\ElectroAnalyzer\src\core\multi_tier_cache.py:626> wait_for=<Future pending cb=[Task.task_wakeup()]>>
Task was destroyed but it is pending!
task: <Task pending name='Task-14300' coro=<MultiTierCacheSystem._metrics_reset_task() running at C:\Users\kevin\Desktop\ElectroAnalyzer\src\core\multi_tier_cache.py:626> wait_for=<Future pending cb=[Task.task_wakeup()]>>
2025-10-21 14:44:51,790 - asyncio - ERROR - Task was destroyed but it is pending!
task: <Task pending name='Task-14284' coro=<MultiTierCacheSystem._metrics_reset_task() running at C:\Users\kevin\Desktop\ElectroAnalyzer\src\core\multi_tier_cache.py:626> wait_for=<Future pending cb=[Task.task_wakeup()]>>
Task was destroyed but it is pending!
task: <Task pending name='Task-14284' coro=<MultiTierCacheSystem._metrics_reset_task() running at C:\Users\kevin\Desktop\ElectroAnalyzer\src\core\multi_tier_cache.py:626> wait_for=<Future pending cb=[Task.task_wakeup()]>>
Task was destroyed but it is pending!
task: <Task pending name='Task-14284' coro=<MultiTierCacheSystem._metrics_reset_task() running at C:\Users\kevin\Desktop\ElectroAnalyzer\src\core\multi_tier_cache.py:626> wait_for=<Future pending cb=[Task.task_wakeup()]>>
2025-10-21 14:44:51,790 - asyncio - ERROR - Task was destroyed but it is pending!
task: <Task pending name='Task-14297' coro=<MultiTierCacheSystem._metrics_reset_task() running at C:\Users\kevin\Desktop\ElectroAnalyzer\src\core\multi_tier_cache.py:626> wait_for=<Future pending cb=[Task.task_wakeup()]>>
Task was destroyed but it is pending!
task: <Task pending name='Task-14297' coro=<MultiTierCacheSystem._metrics_reset_task() running at C:\Users\kevin\Desktop\ElectroAnalyzer\src\core\multi_tier_cache.py:626> wait_for=<Future pending cb=[Task.task_wakeup()]>>
Task was destroyed but it is pending!
task: <Task pending name='Task-14297' coro=<MultiTierCacheSystem._metrics_reset_task() running at C:\Users\kevin\Desktop\ElectroAnalyzer\src\core\multi_tier_cache.py:626> wait_for=<Future pending cb=[Task.task_wakeup()]>>
2025-10-21 14:44:51,790 - asyncio - ERROR - Task was destroyed but it is pending!
task: <Task pending name='Task-14274' coro=<MultiTierCacheSystem._metrics_reset_task() running at C:\Users\kevin\Desktop\ElectroAnalyzer\src\core\multi_tier_cache.py:626> wait_for=<Future pending cb=[Task.task_wakeup()]>>
Task was destroyed but it is pending!
task: <Task pending name='Task-14274' coro=<MultiTierCacheSystem._metrics_reset_task() running at C:\Users\kevin\Desktop\ElectroAnalyzer\src\core\multi_tier_cache.py:626> wait_for=<Future pending cb=[Task.task_wakeup()]>>
Task was destroyed but it is pending!
task: <Task pending name='Task-14274' coro=<MultiTierCacheSystem._metrics_reset_task() running at C:\Users\kevin\Desktop\ElectroAnalyzer\src\core\multi_tier_cache.py:626> wait_for=<Future pending cb=[Task.task_wakeup()]>>
2025-10-21 14:44:51,790 - asyncio - ERROR - Task was destroyed but it is pending!
task: <Task pending name='Task-14296' coro=<MultiTierCacheSystem._cleanup_task() running at C:\Users\kevin\Desktop\ElectroAnalyzer\src\core\multi_tier_cache.py:608> wait_for=<Future pending cb=[Task.task_wakeup()]>>
Task was destroyed but it is pending!
task: <Task pending name='Task-14296' coro=<MultiTierCacheSystem._cleanup_task() running at C:\Users\kevin\Desktop\ElectroAnalyzer\src\core\multi_tier_cache.py:608> wait_for=<Future pending cb=[Task.task_wakeup()]>>
Task was destroyed but it is pending!
task: <Task pending name='Task-14296' coro=<MultiTierCacheSystem._cleanup_task() running at C:\Users\kevin\Desktop\ElectroAnalyzer\src\core\multi_tier_cache.py:608> wait_for=<Future pending cb=[Task.task_wakeup()]>>
2025-10-21 14:44:51,790 - asyncio - ERROR - Task was destroyed but it is pending!
task: <Task pending name='Task-14308' coro=<MultiTierCacheSystem._cleanup_task() running at C:\Users\kevin\Desktop\ElectroAnalyzer\src\core\multi_tier_cache.py:608> wait_for=<Future pending cb=[Task.task_wakeup()]>>
Task was destroyed but it is pending!
task: <Task pending name='Task-14308' coro=<MultiTierCacheSystem._cleanup_task() running at C:\Users\kevin\Desktop\ElectroAnalyzer\src\core\multi_tier_cache.py:608> wait_for=<Future pending cb=[Task.task_wakeup()]>>
Task was destroyed but it is pending!
task: <Task pending name='Task-14308' coro=<MultiTierCacheSystem._cleanup_task() running at C:\Users\kevin\Desktop\ElectroAnalyzer\src\core\multi_tier_cache.py:608> wait_for=<Future pending cb=[Task.task_wakeup()]>>
2025-10-21 14:44:51,790 - asyncio - ERROR - Task was destroyed but it is pending!
task: <Task pending name='Task-14305' coro=<MultiTierCacheSystem._cleanup_task() running at C:\Users\kevin\Desktop\ElectroAnalyzer\src\core\multi_tier_cache.py:608> wait_for=<Future pending cb=[Task.task_wakeup()]>>
Task was destroyed but it is pending!
task: <Task pending name='Task-14305' coro=<MultiTierCacheSystem._cleanup_task() running at C:\Users\kevin\Desktop\ElectroAnalyzer\src\core\multi_tier_cache.py:608> wait_for=<Future pending cb=[Task.task_wakeup()]>>
Task was destroyed but it is pending!
task: <Task pending name='Task-14305' coro=<MultiTierCacheSystem._cleanup_task() running at C:\Users\kevin\Desktop\ElectroAnalyzer\src\core\multi_tier_cache.py:608> wait_for=<Future pending cb=[Task.task_wakeup()]>>
2025-10-21 14:44:51,794 - asyncio - ERROR - Task was destroyed but it is pending!
task: <Task pending name='Task-14302' coro=<MultiTierCacheSystem._cleanup_task() running at C:\Users\kevin\Desktop\ElectroAnalyzer\src\core\multi_tier_cache.py:608> wait_for=<Future pending cb=[Task.task_wakeup()]>>
Task was destroyed but it is pending!
task: <Task pending name='Task-14302' coro=<MultiTierCacheSystem._cleanup_task() running at C:\Users\kevin\Desktop\ElectroAnalyzer\src\core\multi_tier_cache.py:608> wait_for=<Future pending cb=[Task.task_wakeup()]>>
Task was destroyed but it is pending!
task: <Task pending name='Task-14302' coro=<MultiTierCacheSystem._cleanup_task() running at C:\Users\kevin\Desktop\ElectroAnalyzer\src\core\multi_tier_cache.py:608> wait_for=<Future pending cb=[Task.task_wakeup()]>>
2025-10-21 14:44:51,794 - asyncio - ERROR - Task was destroyed but it is pending!
task: <Task pending name='Task-14299' coro=<MultiTierCacheSystem._cleanup_task() running at C:\Users\kevin\Desktop\ElectroAnalyzer\src\core\multi_tier_cache.py:608> wait_for=<Future pending cb=[Task.task_wakeup()]>>
Task was destroyed but it is pending!
task: <Task pending name='Task-14299' coro=<MultiTierCacheSystem._cleanup_task() running at C:\Users\kevin\Desktop\ElectroAnalyzer\src\core\multi_tier_cache.py:608> wait_for=<Future pending cb=[Task.task_wakeup()]>>
Task was destroyed but it is pending!
task: <Task pending name='Task-14299' coro=<MultiTierCacheSystem._cleanup_task() running at C:\Users\kevin\Desktop\ElectroAnalyzer\src\core\multi_tier_cache.py:608> wait_for=<Future pending cb=[Task.task_wakeup()]>>
2025-10-21 14:44:51,794 - asyncio - ERROR - Task was destroyed but it is pending!
task: <Task pending name='Task-14283' coro=<MultiTierCacheSystem._cleanup_task() running at C:\Users\kevin\Desktop\ElectroAnalyzer\src\core\multi_tier_cache.py:608> wait_for=<Future pending cb=[Task.task_wakeup()]>>
Task was destroyed but it is pending!
task: <Task pending name='Task-14283' coro=<MultiTierCacheSystem._cleanup_task() running at C:\Users\kevin\Desktop\ElectroAnalyzer\src\core\multi_tier_cache.py:608> wait_for=<Future pending cb=[Task.task_wakeup()]>>
Task was destroyed but it is pending!
task: <Task pending name='Task-14283' coro=<MultiTierCacheSystem._cleanup_task() running at C:\Users\kevin\Desktop\ElectroAnalyzer\src\core\multi_tier_cache.py:608> wait_for=<Future pending cb=[Task.task_wakeup()]>>
2025-10-21 14:44:51,794 - asyncio - ERROR - Task was destroyed but it is pending!
task: <Task pending name='Task-14293' coro=<MultiTierCacheSystem._cleanup_task() running at C:\Users\kevin\Desktop\ElectroAnalyzer\src\core\multi_tier_cache.py:608> wait_for=<Future pending cb=[Task.task_wakeup()]>>
Task was destroyed but it is pending!
task: <Task pending name='Task-14293' coro=<MultiTierCacheSystem._cleanup_task() running at C:\Users\kevin\Desktop\ElectroAnalyzer\src\core\multi_tier_cache.py:608> wait_for=<Future pending cb=[Task.task_wakeup()]>>
Task was destroyed but it is pending!
task: <Task pending name='Task-14293' coro=<MultiTierCacheSystem._cleanup_task() running at C:\Users\kevin\Desktop\ElectroAnalyzer\src\core\multi_tier_cache.py:608> wait_for=<Future pending cb=[Task.task_wakeup()]>>
2025-10-21 14:44:51,795 - asyncio - ERROR - Task was destroyed but it is pending!
task: <Task pending name='Task-14289' coro=<MultiTierCacheSystem._cleanup_task() running at C:\Users\kevin\Desktop\ElectroAnalyzer\src\core\multi_tier_cache.py:608> wait_for=<Future pending cb=[Task.task_wakeup()]>>
Task was destroyed but it is pending!
task: <Task pending name='Task-14289' coro=<MultiTierCacheSystem._cleanup_task() running at C:\Users\kevin\Desktop\ElectroAnalyzer\src\core\multi_tier_cache.py:608> wait_for=<Future pending cb=[Task.task_wakeup()]>>
Task was destroyed but it is pending!
task: <Task pending name='Task-14289' coro=<MultiTierCacheSystem._cleanup_task() running at C:\Users\kevin\Desktop\ElectroAnalyzer\src\core\multi_tier_cache.py:608> wait_for=<Future pending cb=[Task.task_wakeup()]>>
2025-10-21 14:44:51,795 - asyncio - ERROR - Task was destroyed but it is pending!
task: <Task pending name='Task-14273' coro=<MultiTierCacheSystem._cleanup_task() running at C:\Users\kevin\Desktop\ElectroAnalyzer\src\core\multi_tier_cache.py:608> wait_for=<Future pending cb=[Task.task_wakeup()]>>
Task was destroyed but it is pending!
task: <Task pending name='Task-14273' coro=<MultiTierCacheSystem._cleanup_task() running at C:\Users\kevin\Desktop\ElectroAnalyzer\src\core\multi_tier_cache.py:608> wait_for=<Future pending cb=[Task.task_wakeup()]>>
Task was destroyed but it is pending!
task: <Task pending name='Task-14273' coro=<MultiTierCacheSystem._cleanup_task() running at C:\Users\kevin\Desktop\ElectroAnalyzer\src\core\multi_tier_cache.py:608> wait_for=<Future pending cb=[Task.task_wakeup()]>>
2025-10-21 14:44:51,795 - asyncio - ERROR - Task was destroyed but it is pending!
task: <Task pending name='Task-14277' coro=<MultiTierCacheSystem._cleanup_task() running at C:\Users\kevin\Desktop\ElectroAnalyzer\src\core\multi_tier_cache.py:608> wait_for=<Future pending cb=[Task.task_wakeup()]>>
Task was destroyed but it is pending!
task: <Task pending name='Task-14277' coro=<MultiTierCacheSystem._cleanup_task() running at C:\Users\kevin\Desktop\ElectroAnalyzer\src\core\multi_tier_cache.py:608> wait_for=<Future pending cb=[Task.task_wakeup()]>>
Task was destroyed but it is pending!
task: <Task pending name='Task-14277' coro=<MultiTierCacheSystem._cleanup_task() running at C:\Users\kevin\Desktop\ElectroAnalyzer\src\core\multi_tier_cache.py:608> wait_for=<Future pending cb=[Task.task_wakeup()]>>
  C:\Users\kevin\AppData\Local\Programs\Python\Python311\Lib\json\encoder.py:432: RuntimeWarning: coroutine 'TestExecutionEngine.test_execute_test_no_runner' was never awaited
    yield from _iterencode_dict(o, _current_indent_level)
  Enable tracemalloc to get traceback where the object was allocated.
  See https://docs.pytest.org/en/stable/how-to/capture-warnings.html#resource-warnings for more info.

tests/unit/test_query_expander.py::TestMedicalVocabulary::test_save_and_load_vocabulary
  C:\Users\kevin\AppData\Local\Programs\Python\Python311\Lib\json\encoder.py:432: RuntimeWarning: coroutine 'TestPerformanceTestOrchestrator.test_run_optimization_tests' was never awaited
    yield from _iterencode_dict(o, _current_indent_level)
  Enable tracemalloc to get traceback where the object was allocated.
  See https://docs.pytest.org/en/stable/how-to/capture-warnings.html#resource-warnings for more info.

tests/unit/test_query_expander.py::TestMedicalVocabulary::test_save_and_load_vocabulary
  C:\Users\kevin\AppData\Local\Programs\Python\Python311\Lib\json\encoder.py:432: RuntimeWarning: coroutine 'test_integration_full_workflow' was never awaited
    yield from _iterencode_dict(o, _current_indent_level)
  Enable tracemalloc to get traceback where the object was allocated.
  See https://docs.pytest.org/en/stable/how-to/capture-warnings.html#resource-warnings for more info.

tests/unit/test_system_integration_service.py::TestSystemIntegrationService::test_get_system_metrics
tests/unit/test_system_integration_service.py::TestSystemIntegrationService::test_system_optimization
tests/unit/test_system_integration_service.py::TestSystemIntegrationService::test_system_optimization_aggressive_mode
tests/unit/test_system_integration_service.py::TestSystemIntegrationService::test_callback_registration
tests/unit/test_system_integration_service.py::TestSystemIntegrationService::test_system_status_report
tests/unit/test_system_integration_service.py::TestIntegration::test_end_to_end_system_integration
tests/unit/test_system_integration_service.py::TestIntegration::test_service_lifecycle
tests/unit/test_system_integration_service.py::TestIntegration::test_auto_optimization_trigger
  C:\Users\kevin\Desktop\ElectroAnalyzer\venv_test\Lib\site-packages\_pytest\stash.py:108: RuntimeWarning: coroutine 'PerformanceOptimizer.analyze_performance' was never awaited
    del self._storage[key]
  Enable tracemalloc to get traceback where the object was allocated.
  See https://docs.pytest.org/en/stable/how-to/capture-warnings.html#resource-warnings for more info.

tests/unit/test_system_integration_service.py::TestIntegration::test_end_to_end_system_integration
  C:\Users\kevin\Desktop\ElectroAnalyzer\venv_test\Lib\site-packages\_pytest\stash.py:108: RuntimeWarning: coroutine 'PerformanceOptimizer.optimize_performance' was never awaited
    del self._storage[key]
  Enable tracemalloc to get traceback where the object was allocated.
  See https://docs.pytest.org/en/stable/how-to/capture-warnings.html#resource-warnings for more info.

-- Docs: https://docs.pytest.org/en/stable/how-to/capture-warnings.html
=========================== short test summary info ===========================
FAILED tests/e2e/test_document_analysis_workflow.py::TestDocumentAnalysisWorkflow::test_complete_analysis_workflow
FAILED tests/e2e/test_document_analysis_workflow.py::TestDocumentAnalysisWorkflow::test_analysis_with_different_document_types
FAILED tests/e2e/test_document_analysis_workflow.py::TestDocumentAnalysisWorkflow::test_concurrent_analysis
FAILED tests/e2e/test_plugin_system_workflow.py::TestPluginSystemWorkflow::test_plugin_discovery_workflow
FAILED tests/e2e/test_plugin_system_workflow.py::TestPluginSystemWorkflow::test_plugin_lifecycle_management
FAILED tests/e2e/test_plugin_system_workflow.py::TestPluginSystemWorkflow::test_plugin_integration_with_analysis
FAILED tests/integration/test_enhanced_features_integration.py::TestEnhancedFeaturesIntegration::test_websocket_integration
FAILED tests/integration/test_enhanced_features_integration.py::TestEnhancedFeaturesIntegration::test_database_integration
FAILED tests/integration/test_enhanced_features_integration.py::TestPerformanceIntegration::test_metrics_collection_integration
FAILED tests/integration/test_enhanced_features_integration.py::TestPerformanceIntegration::test_performance_monitoring_integration
FAILED tests/performance/test_load_performance.py::TestPerformanceLoad::test_single_request_performance
FAILED tests/performance/test_load_performance.py::TestPerformanceLoad::test_metrics_collection_performance
FAILED tests/performance/test_load_performance.py::TestPerformanceLoad::test_memory_usage_under_load
FAILED tests/performance/test_load_performance.py::TestPerformanceLoad::test_websocket_performance
FAILED tests/performance/test_load_performance.py::TestPerformanceLoad::test_security_headers_performance
FAILED tests/performance/test_load_performance.py::TestPerformanceLoad::test_rate_limiting_performance
FAILED tests/performance/test_load_performance.py::TestStressTesting::test_sustained_load_stress
FAILED tests/test_new_components.py::TestUnifiedMLSystem::test_performance_monitoring
FAILED tests/test_new_components.py::TestTypeSafety::test_string_validator - ...
FAILED tests/test_new_components.py::TestTypeSafety::test_email_validator - N...
FAILED tests/test_new_components.py::TestTypeSafety::test_error_handler - Nam...
FAILED tests/test_new_components.py::TestPerformance::test_ml_system_performance
FAILED tests/unit/test_analysis_service_pipeline.py::test_analysis_service_uses_analysis_utils
FAILED tests/unit/test_database_crud.py::test_get_rubric - assert None is not...
FAILED tests/unit/test_database_crud.py::test_update_rubric - AttributeError:...
FAILED tests/unit/test_database_crud.py::test_delete_rubric - assert False is...
FAILED tests/unit/test_enhanced_error_context.py::TestEnhancedExceptionHandler::test_generic_exception_handling
FAILED tests/unit/test_enhanced_error_context.py::TestEnhancedExceptionHandler::test_debug_mode_response
FAILED tests/unit/test_enhanced_error_context.py::TestEnhancedExceptionHandler::test_error_handler_exception_safety
FAILED tests/unit/test_llm_service_backend.py::test_transformers_generate_applies_stop_sequences
FAILED tests/unit/test_metrics_collector.py::TestSystemMetricsSource::test_system_metrics_collection
FAILED tests/unit/test_metrics_collector.py::TestSystemMetricsSource::test_system_metrics_error_handling
FAILED tests/unit/test_metrics_collector.py::TestApplicationMetricsSource::test_application_metrics_collection
FAILED tests/unit/test_metrics_collector.py::TestAIModelMetricsSource::test_ai_metrics_collection
FAILED tests/unit/test_metrics_collector.py::TestMetricsCollector::test_metrics_collection
FAILED tests/unit/test_ml_trainer.py::TestMLTrainingPipeline::test_insufficient_training_data
FAILED tests/unit/test_ml_trainer.py::TestMLTrainingPipeline::test_successful_training_and_deployment
FAILED tests/unit/test_ml_trainer.py::TestMLTrainingPipeline::test_training_with_insufficient_improvement
FAILED tests/unit/test_ml_trainer.py::TestMLTrainingPipeline::test_training_error_handling
FAILED tests/unit/test_ml_trainer.py::TestMLTrainingPipeline::test_skipped_training_due_to_time
FAILED tests/unit/test_ml_trainer.py::test_legacy_function_compatibility - Ru...
FAILED tests/unit/test_ml_trainer.py::TestMLTrainingIntegration::test_end_to_end_training_pipeline
FAILED tests/unit/test_performance_metrics.py::TestMetricsCollector::test_high_memory_warning
FAILED tests/unit/test_performance_optimizer.py::TestBatchCacheOperations::test_batch_get_embeddings
FAILED tests/unit/test_performance_optimizer.py::TestBatchCacheOperations::test_batch_set_embeddings
FAILED tests/unit/test_performance_optimizer.py::TestBatchCacheOperations::test_batch_get_ner_results
FAILED tests/unit/test_performance_optimizer.py::TestCacheWarmingService::test_execute_warming
FAILED tests/unit/test_performance_optimizer.py::TestPerformanceOptimizer::test_analyze_performance
FAILED tests/unit/test_performance_optimizer.py::TestPerformanceOptimizer::test_optimize_performance
FAILED tests/unit/test_performance_optimizer.py::TestPerformanceOptimizer::test_identify_bottlenecks
FAILED tests/unit/test_performance_optimizer.py::TestPerformanceOptimizer::test_generate_optimization_recommendations
FAILED tests/unit/test_performance_optimizer.py::TestPerformanceOptimizer::test_calculate_performance_improvements
FAILED tests/unit/test_performance_optimizer.py::TestPerformanceOptimizer::test_memory_optimization
FAILED tests/unit/test_performance_optimizer.py::TestPerformanceOptimizer::test_proactive_warming
FAILED tests/unit/test_performance_test_orchestrator.py::TestExecutionEngine::test_execute_test_success
FAILED tests/unit/test_performance_test_orchestrator.py::TestExecutionEngine::test_execute_test_failure
FAILED tests/unit/test_performance_test_orchestrator.py::TestExecutionEngine::test_execute_test_timeout
FAILED tests/unit/test_performance_test_orchestrator.py::TestExecutionEngine::test_execute_test_no_runner
FAILED tests/unit/test_performance_test_orchestrator.py::TestExecutionEngine::test_execute_tests_parallel
FAILED tests/unit/test_performance_test_orchestrator.py::TestExecutionEngine::test_execute_tests_parallel_with_disabled
FAILED tests/unit/test_performance_test_orchestrator.py::TestPerformanceTestOrchestrator::test_run_baseline_tests
FAILED tests/unit/test_performance_test_orchestrator.py::TestPerformanceTestOrchestrator::test_run_optimization_tests
FAILED tests/unit/test_performance_test_orchestrator.py::TestPerformanceTestOrchestrator::test_run_test_suite
FAILED tests/unit/test_performance_test_orchestrator.py::TestPerformanceTestOrchestrator::test_run_full_performance_suite
FAILED tests/unit/test_performance_test_orchestrator.py::TestPerformanceTestOrchestrator::test_run_nonexistent_suite
FAILED tests/unit/test_performance_test_orchestrator.py::test_integration_full_workflow
ERROR tests/test_api_analysis.py::test_analyze_document_api_route - apschedul...
ERROR tests/test_api_analysis.py::test_analyze_document_rejects_invalid_strictness
ERROR tests/test_api_analysis.py::test_analyze_document_rejects_oversized_file
ERROR tests/test_new_components.py::TestSecurityMiddleware::test_sql_injection_detection
ERROR tests/test_new_components.py::TestSecurityMiddleware::test_xss_detection
ERROR tests/test_new_components.py::TestSecurityMiddleware::test_rate_limiting
66 failed, 685 passed, 28 skipped, 44 warnings, 6 errors in 1701.86s (0:28:21)
--- Logging error ---
Traceback (most recent call last):
  File "C:\Users\kevin\AppData\Local\Programs\Python\Python311\Lib\logging\__init__.py", line 1113, in emit
    stream.write(msg + self.terminator)
ValueError: I/O operation on closed file.
Call stack:
  File "C:\Users\kevin\Desktop\ElectroAnalyzer\src\core\memory_manager.py", line 449, in stop
    logger.info("Memory manager stopped")
Message: 'Memory manager stopped'
Arguments: ()
--- Logging error ---
Traceback (most recent call last):
  File "C:\Users\kevin\AppData\Local\Programs\Python\Python311\Lib\logging\__init__.py", line 1113, in emit
    stream.write(msg + self.terminator)
ValueError: I/O operation on closed file.
Call stack:
  File "C:\Users\kevin\Desktop\ElectroAnalyzer\src\core\memory_manager.py", line 449, in stop
    logger.info("Memory manager stopped")
Message: 'Memory manager stopped'
Arguments: ()
--- Logging error ---
Traceback (most recent call last):
  File "C:\Users\kevin\AppData\Local\Programs\Python\Python311\Lib\logging\__init__.py", line 1113, in emit
    stream.write(msg + self.terminator)
ValueError: I/O operation on closed file.
Call stack:
  File "C:\Users\kevin\Desktop\ElectroAnalyzer\src\core\memory_manager.py", line 449, in stop
    logger.info("Memory manager stopped")
Message: 'Memory manager stopped'
Arguments: ()
